    return func(*args, **kwargs)
  File "/./service_main.py", line 76, in get_author
    logging.warning(">>> Error Connecting:", errc)
Message: '>>> Error Connecting:'
Arguments: (ConnectionError(MaxRetryError("HTTPConnectionPool(host='service_author', port=8081): Max retries exceeded with url: /authors/2 (Caused by NewConnectionError('<urllib3.connection.HTTPConnection object at 0x7f8afb55e140>: Failed to establish a new connection: [Errno 111] Connection refused'))")),)
WARNING:root:Circuit "get_author" is "open", failures: 9
WARNING:root:
CRITICAL:root:Circuit OPEN
WARNING:root:Circuit "get_author" is "open", failures: 9
INFO:     172.19.0.1:56290 - "GET /presentationsAndAuthor/Second%20Presentation HTTP/1.1" 500 Internal Server Error
INFO:     172.19.0.1:56290 - "GET /presentationsAndAuthor/Second%20Presentation HTTP/1.1" 200 OK
INFO:     172.19.0.1:56290 - "GET /presentationsAndAuthor/Second%20Presentation HTTP/1.1" 200 OK
INFO:     172.19.0.1:56290 - "GET /presentationsAndAuthor/Second%20Presentation HTTP/1.1" 200 OK
INFO:     172.19.0.1:56290 - "GET /presentationsAndAuthor/Second%20Presentation HTTP/1.1" 200 OK
Griffiths
INFO:     172.19.0.1:56290 - "GET /presentationsAndAuthor/Second%20Presentation HTTP/1.1" 200 OK
WARNING:root:
WARNING:root:Circuit "get_author" is "open", failures: 9
WARNING:root:
CRITICAL:root:Circuit OPEN
WARNING:root:Circuit "get_author" is "open", failures: 9
WARNING:root:
WARNING:root:Circuit "get_author" is "open", failures: 9
WARNING:root:
WARNING:root:Circuit "get_author" is "open", failures: 9
CRITICAL:root:Circuit OPEN
WARNING:root:
WARNING:root:Circuit "get_author" is "open", failures: 9
WARNING:root:
CRITICAL:root:Circuit OPEN
WARNING:root:Circuit "get_author" is "open", failures: 9
WARNING:root:
WARNING:root:Circuit "get_author" is "open", failures: 9
WARNING:root:
WARNING:root:Circuit "get_author" is "half_open", failures: 9
WARNING:root:
WARNING:root:Circuit "get_author" is "closed", failures: 0
WARNING:root:
WARNING:root:Circuit "get_author" is "closed", failures: 0
WARNING:root:
WARNING:root:Circuit "get_author" is "closed", failures: 0
WARNING:root:
WARNING:root:Circuit "get_author" is "closed", failures: 0
WARNING:root:
WARNING:root:Circuit "get_author" is "closed", failures: 0
WARNING:root:
WARNING:root:Circuit "get_author" is "closed", failures: 0
WARNING:root:
WARNING:root:Circuit "get_author" is "closed", failures: 0
WARNING:root:
WARNING:root:Circuit "get_author" is "closed", failures: 0
WARNING:root:
WARNING:root:Circuit "get_author" is "closed", failures: 0
WARNING:root:
WARNING:root:Circuit "get_author" is "closed", failures: 0
WARNING:root:
WARNING:root:Circuit "get_author" is "closed", failures: 0
WARNING:root:
WARNING:root:Circuit "get_author" is "closed", failures: 0
WARNING:root:
WARNING:root:Circuit "get_author" is "closed", failures: 0
WARNING:root:
WARNING:root:Circuit "get_author" is "closed", failures: 0
WARNING:root:
WARNING:root:Circuit "get_author" is "closed", failures: 0
WARNING:root:
WARNING:root:Circuit "get_author" is "closed", failures: 0
WARNING:root:
WARNING:root:Circuit "get_author" is "closed", failures: 0
WARNING:root:
WARNING:root:Circuit "get_author" is "closed", failures: 0
WARNING:root:
WARNING:root:Circuit "get_author" is "closed", failures: 0
WARNING:root:
WARNING:root:Circuit "get_author" is "closed", failures: 0
WARNING:root:
WARNING:root:Circuit "get_author" is "closed", failures: 0
WARNING:root:
WARNING:root:Circuit "get_author" is "closed", failures: 0
WARNING:root:
WARNING:root:Circuit "get_author" is "closed", failures: 0
WARNING:root:
WARNING:root:Circuit "get_author" is "closed", failures: 0
WARNING:root:
WARNING:root:Circuit "get_author" is "closed", failures: 0
WARNING:root:
WARNING:root:Circuit "get_author" is "closed", failures: 0
WARNING:root:
WARNING:root:Circuit "get_author" is "closed", failures: 0
WARNING:root:
WARNING:root:Circuit "get_author" is "closed", failures: 0
WARNING:root:
WARNING:root:Circuit "get_author" is "closed", failures: 0
WARNING:root:
WARNING:root:Circuit "get_author" is "closed", failures: 0
WARNING:root:
--- Logging error ---
Traceback (most recent call last):
  File "/usr/local/lib/python3.10/dist-packages/urllib3/connection.py", line 174, in _new_conn
    conn = connection.create_connection(
  File "/usr/local/lib/python3.10/dist-packages/urllib3/util/connection.py", line 72, in create_connection
    for res in socket.getaddrinfo(host, port, family, socket.SOCK_STREAM):
  File "/usr/lib/python3.10/socket.py", line 955, in getaddrinfo
    for res in _socket.getaddrinfo(host, port, family, type, proto, flags):
socket.gaierror: [Errno -2] Name or service not known

During handling of the above exception, another exception occurred:

Traceback (most recent call last):
  File "/usr/local/lib/python3.10/dist-packages/urllib3/connectionpool.py", line 703, in urlopen
    httplib_response = self._make_request(
  File "/usr/local/lib/python3.10/dist-packages/urllib3/connectionpool.py", line 398, in _make_request
    conn.request(method, url, **httplib_request_kw)
  File "/usr/local/lib/python3.10/dist-packages/urllib3/connection.py", line 239, in request
    super(HTTPConnection, self).request(method, url, body=body, headers=headers)
  File "/usr/lib/python3.10/http/client.py", line 1282, in request
    self._send_request(method, url, body, headers, encode_chunked)
  File "/usr/lib/python3.10/http/client.py", line 1328, in _send_request
    self.endheaders(body, encode_chunked=encode_chunked)
  File "/usr/lib/python3.10/http/client.py", line 1277, in endheaders
    self._send_output(message_body, encode_chunked=encode_chunked)
  File "/usr/lib/python3.10/http/client.py", line 1037, in _send_output
    self.send(msg)
  File "/usr/lib/python3.10/http/client.py", line 975, in send
    self.connect()
  File "/usr/local/lib/python3.10/dist-packages/urllib3/connection.py", line 205, in connect
    conn = self._new_conn()
  File "/usr/local/lib/python3.10/dist-packages/urllib3/connection.py", line 186, in _new_conn
    raise NewConnectionError(
urllib3.exceptions.NewConnectionError: <urllib3.connection.HTTPConnection object at 0x7f8afb55e950>: Failed to establish a new connection: [Errno -2] Name or service not known

During handling of the above exception, another exception occurred:

Traceback (most recent call last):
  File "/usr/local/lib/python3.10/dist-packages/requests/adapters.py", line 489, in send
    resp = conn.urlopen(
  File "/usr/local/lib/python3.10/dist-packages/urllib3/connectionpool.py", line 787, in urlopen
    retries = retries.increment(
  File "/usr/local/lib/python3.10/dist-packages/urllib3/util/retry.py", line 592, in increment
    raise MaxRetryError(_pool, url, error or ResponseError(cause))
urllib3.exceptions.MaxRetryError: HTTPConnectionPool(host='service_author', port=8081): Max retries exceeded with url: /authors/2 (Caused by NewConnectionError('<urllib3.connection.HTTPConnection object at 0x7f8afb55e950>: Failed to establish a new connection: [Errno -2] Name or service not known'))

During handling of the above exception, another exception occurred:

Traceback (most recent call last):
  File "/./service_main.py", line 74, in get_author
    response_author = requests.get("http://" + service_author + "/authors/" + str(id))
  File "/usr/local/lib/python3.10/dist-packages/requests/api.py", line 73, in get
    return request("get", url, params=params, **kwargs)
  File "/usr/local/lib/python3.10/dist-packages/requests/api.py", line 59, in request
    return session.request(method=method, url=url, **kwargs)
  File "/usr/local/lib/python3.10/dist-packages/requests/sessions.py", line 587, in request
    resp = self.send(prep, **send_kwargs)
  File "/usr/local/lib/python3.10/dist-packages/requests/sessions.py", line 701, in send
    r = adapter.send(request, **kwargs)
  File "/usr/local/lib/python3.10/dist-packages/requests/adapters.py", line 565, in send
    raise ConnectionError(e, request=request)
requests.exceptions.ConnectionError: HTTPConnectionPool(host='service_author', port=8081): Max retries exceeded with url: /authors/2 (Caused by NewConnectionError('<urllib3.connection.HTTPConnection object at 0x7f8afb55e950>: Failed to establish a new connection: [Errno -2] Name or service not known'))

During handling of the above exception, another exception occurred:

Traceback (most recent call last):
  File "/usr/lib/python3.10/logging/__init__.py", line 1100, in emit
    msg = self.format(record)
  File "/usr/lib/python3.10/logging/__init__.py", line 943, in format
    return fmt.format(record)
  File "/usr/lib/python3.10/logging/__init__.py", line 678, in format
    record.message = record.getMessage()
  File "/usr/lib/python3.10/logging/__init__.py", line 368, in getMessage
    msg = msg % self.args
TypeError: not all arguments converted during string formatting
Call stack:
  File "<string>", line 1, in <module>
  File "/usr/lib/python3.10/multiprocessing/spawn.py", line 116, in spawn_main
    exitcode = _main(fd, parent_sentinel)
  File "/usr/lib/python3.10/multiprocessing/spawn.py", line 129, in _main
    return self._bootstrap(parent_sentinel)
  File "/usr/lib/python3.10/multiprocessing/process.py", line 314, in _bootstrap
    self.run()
  File "/usr/lib/python3.10/multiprocessing/process.py", line 108, in run
    self._target(*self._args, **self._kwargs)
INFO:     172.19.0.1:56308 - "GET /presentationsAndAuthor/Second%20Presentation HTTP/1.1" 500 Internal Server Error
  File "/usr/local/lib/python3.10/dist-packages/uvicorn/_subprocess.py", line 76, in subprocess_started
    target(sockets=sockets)
  File "/usr/local/lib/python3.10/dist-packages/uvicorn/server.py", line 60, in run
    return asyncio.run(self.serve(sockets=sockets))
  File "/usr/lib/python3.10/asyncio/runners.py", line 44, in run
    return loop.run_until_complete(main)
  File "/usr/lib/python3.10/asyncio/base_events.py", line 633, in run_until_complete
    self.run_forever()
  File "/usr/lib/python3.10/asyncio/base_events.py", line 600, in run_forever
    self._run_once()
  File "/usr/lib/python3.10/asyncio/base_events.py", line 1896, in _run_once
    handle._run()
  File "/usr/lib/python3.10/asyncio/events.py", line 80, in _run
    self._context.run(self._callback, *self._args)
  File "/usr/local/lib/python3.10/dist-packages/uvicorn/protocols/http/httptools_impl.py", line 419, in run_asgi
    result = await app(  # type: ignore[func-returns-value]
  File "/usr/local/lib/python3.10/dist-packages/uvicorn/middleware/proxy_headers.py", line 78, in __call__
    return await self.app(scope, receive, send)
  File "/usr/local/lib/python3.10/dist-packages/fastapi/applications.py", line 271, in __call__
    await super().__call__(scope, receive, send)
  File "/usr/local/lib/python3.10/dist-packages/starlette/applications.py", line 118, in __call__
    await self.middleware_stack(scope, receive, send)
  File "/usr/local/lib/python3.10/dist-packages/starlette/middleware/errors.py", line 162, in __call__
    await self.app(scope, receive, _send)
  File "/usr/local/lib/python3.10/dist-packages/starlette/middleware/exceptions.py", line 68, in __call__
    await self.app(scope, receive, sender)
  File "/usr/local/lib/python3.10/dist-packages/fastapi/middleware/asyncexitstack.py", line 18, in __call__
    await self.app(scope, receive, send)
  File "/usr/local/lib/python3.10/dist-packages/starlette/routing.py", line 706, in __call__
    await route.handle(scope, receive, send)
  File "/usr/local/lib/python3.10/dist-packages/starlette/routing.py", line 276, in handle
    await self.app(scope, receive, send)
  File "/usr/local/lib/python3.10/dist-packages/starlette/routing.py", line 66, in app
    response = await func(request)
  File "/usr/local/lib/python3.10/dist-packages/fastapi/routing.py", line 237, in app
    raw_response = await run_endpoint_function(
  File "/usr/local/lib/python3.10/dist-packages/fastapi/routing.py", line 163, in run_endpoint_function
    return await dependant.call(**values)
  File "/./service_main.py", line 105, in read_presentation
    author = get_author(presentation.author_id)
  File "/./circuitbreaker.py", line 159, in wrapper
    return call(function, *args, **kwargs)
  File "/./circuitbreaker.py", line 170, in call
    return func(*args, **kwargs)
  File "/./service_main.py", line 76, in get_author
    logging.warning(">>> Error Connecting:", errc)
Message: '>>> Error Connecting:'
Arguments: (ConnectionError(MaxRetryError("HTTPConnectionPool(host='service_author', port=8081): Max retries exceeded with url: /authors/2 (Caused by NewConnectionError('<urllib3.connection.HTTPConnection object at 0x7f8afb55e950>: Failed to establish a new connection: [Errno -2] Name or service not known'))")),)
WARNING:root:Circuit "get_author" is "closed", failures: 1
WARNING:root:
--- Logging error ---
Traceback (most recent call last):
  File "/usr/local/lib/python3.10/dist-packages/urllib3/connection.py", line 174, in _new_conn
    conn = connection.create_connection(
  File "/usr/local/lib/python3.10/dist-packages/urllib3/util/connection.py", line 72, in create_connection
    for res in socket.getaddrinfo(host, port, family, socket.SOCK_STREAM):
  File "/usr/lib/python3.10/socket.py", line 955, in getaddrinfo
    for res in _socket.getaddrinfo(host, port, family, type, proto, flags):
socket.gaierror: [Errno -2] Name or service not known

During handling of the above exception, another exception occurred:

Traceback (most recent call last):
  File "/usr/local/lib/python3.10/dist-packages/urllib3/connectionpool.py", line 703, in urlopen
    httplib_response = self._make_request(
  File "/usr/local/lib/python3.10/dist-packages/urllib3/connectionpool.py", line 398, in _make_request
    conn.request(method, url, **httplib_request_kw)
  File "/usr/local/lib/python3.10/dist-packages/urllib3/connection.py", line 239, in request
    super(HTTPConnection, self).request(method, url, body=body, headers=headers)
  File "/usr/lib/python3.10/http/client.py", line 1282, in request
    self._send_request(method, url, body, headers, encode_chunked)
  File "/usr/lib/python3.10/http/client.py", line 1328, in _send_request
    self.endheaders(body, encode_chunked=encode_chunked)
  File "/usr/lib/python3.10/http/client.py", line 1277, in endheaders
    self._send_output(message_body, encode_chunked=encode_chunked)
  File "/usr/lib/python3.10/http/client.py", line 1037, in _send_output
    self.send(msg)
  File "/usr/lib/python3.10/http/client.py", line 975, in send
    self.connect()
  File "/usr/local/lib/python3.10/dist-packages/urllib3/connection.py", line 205, in connect
    conn = self._new_conn()
  File "/usr/local/lib/python3.10/dist-packages/urllib3/connection.py", line 186, in _new_conn
    raise NewConnectionError(
urllib3.exceptions.NewConnectionError: <urllib3.connection.HTTPConnection object at 0x7f8afb55f2e0>: Failed to establish a new connection: [Errno -2] Name or service not known

During handling of the above exception, another exception occurred:

Traceback (most recent call last):
  File "/usr/local/lib/python3.10/dist-packages/requests/adapters.py", line 489, in send
    resp = conn.urlopen(
  File "/usr/local/lib/python3.10/dist-packages/urllib3/connectionpool.py", line 787, in urlopen
    retries = retries.increment(
  File "/usr/local/lib/python3.10/dist-packages/urllib3/util/retry.py", line 592, in increment
    raise MaxRetryError(_pool, url, error or ResponseError(cause))
urllib3.exceptions.MaxRetryError: HTTPConnectionPool(host='service_author', port=8081): Max retries exceeded with url: /authors/2 (Caused by NewConnectionError('<urllib3.connection.HTTPConnection object at 0x7f8afb55f2e0>: Failed to establish a new connection: [Errno -2] Name or service not known'))

During handling of the above exception, another exception occurred:

Traceback (most recent call last):
  File "/./service_main.py", line 74, in get_author
    response_author = requests.get("http://" + service_author + "/authors/" + str(id))
  File "/usr/local/lib/python3.10/dist-packages/requests/api.py", line 73, in get
    return request("get", url, params=params, **kwargs)
  File "/usr/local/lib/python3.10/dist-packages/requests/api.py", line 59, in request
    return session.request(method=method, url=url, **kwargs)
  File "/usr/local/lib/python3.10/dist-packages/requests/sessions.py", line 587, in request
    resp = self.send(prep, **send_kwargs)
  File "/usr/local/lib/python3.10/dist-packages/requests/sessions.py", line 701, in send
    r = adapter.send(request, **kwargs)
  File "/usr/local/lib/python3.10/dist-packages/requests/adapters.py", line 565, in send
    raise ConnectionError(e, request=request)
requests.exceptions.ConnectionError: HTTPConnectionPool(host='service_author', port=8081): Max retries exceeded with url: /authors/2 (Caused by NewConnectionError('<urllib3.connection.HTTPConnection object at 0x7f8afb55f2e0>: Failed to establish a new connection: [Errno -2] Name or service not known'))

During handling of the above exception, another exception occurred:

Traceback (most recent call last):
  File "/usr/lib/python3.10/logging/__init__.py", line 1100, in emit
    msg = self.format(record)
  File "/usr/lib/python3.10/logging/__init__.py", line 943, in format
    return fmt.format(record)
  File "/usr/lib/python3.10/logging/__init__.py", line 678, in format
    record.message = record.getMessage()
  File "/usr/lib/python3.10/logging/__init__.py", line 368, in getMessage
    msg = msg % self.args
TypeError: not all arguments converted during string formatting
Call stack:
  File "<string>", line 1, in <module>
INFO:     172.19.0.1:56308 - "GET /presentationsAndAuthor/Second%20Presentation HTTP/1.1" 500 Internal Server Error
  File "/usr/lib/python3.10/multiprocessing/spawn.py", line 116, in spawn_main
    exitcode = _main(fd, parent_sentinel)
  File "/usr/lib/python3.10/multiprocessing/spawn.py", line 129, in _main
    return self._bootstrap(parent_sentinel)
  File "/usr/lib/python3.10/multiprocessing/process.py", line 314, in _bootstrap
    self.run()
  File "/usr/lib/python3.10/multiprocessing/process.py", line 108, in run
    self._target(*self._args, **self._kwargs)
  File "/usr/local/lib/python3.10/dist-packages/uvicorn/_subprocess.py", line 76, in subprocess_started
    target(sockets=sockets)
  File "/usr/local/lib/python3.10/dist-packages/uvicorn/server.py", line 60, in run
    return asyncio.run(self.serve(sockets=sockets))
  File "/usr/lib/python3.10/asyncio/runners.py", line 44, in run
    return loop.run_until_complete(main)
  File "/usr/lib/python3.10/asyncio/base_events.py", line 633, in run_until_complete
    self.run_forever()
  File "/usr/lib/python3.10/asyncio/base_events.py", line 600, in run_forever
    self._run_once()
  File "/usr/lib/python3.10/asyncio/base_events.py", line 1896, in _run_once
    handle._run()
  File "/usr/lib/python3.10/asyncio/events.py", line 80, in _run
    self._context.run(self._callback, *self._args)
  File "/usr/local/lib/python3.10/dist-packages/uvicorn/protocols/http/httptools_impl.py", line 419, in run_asgi
    result = await app(  # type: ignore[func-returns-value]
  File "/usr/local/lib/python3.10/dist-packages/uvicorn/middleware/proxy_headers.py", line 78, in __call__
    return await self.app(scope, receive, send)
  File "/usr/local/lib/python3.10/dist-packages/fastapi/applications.py", line 271, in __call__
    await super().__call__(scope, receive, send)
  File "/usr/local/lib/python3.10/dist-packages/starlette/applications.py", line 118, in __call__
    await self.middleware_stack(scope, receive, send)
  File "/usr/local/lib/python3.10/dist-packages/starlette/middleware/errors.py", line 162, in __call__
    await self.app(scope, receive, _send)
  File "/usr/local/lib/python3.10/dist-packages/starlette/middleware/exceptions.py", line 68, in __call__
    await self.app(scope, receive, sender)
  File "/usr/local/lib/python3.10/dist-packages/fastapi/middleware/asyncexitstack.py", line 18, in __call__
    await self.app(scope, receive, send)
  File "/usr/local/lib/python3.10/dist-packages/starlette/routing.py", line 706, in __call__
    await route.handle(scope, receive, send)
  File "/usr/local/lib/python3.10/dist-packages/starlette/routing.py", line 276, in handle
    await self.app(scope, receive, send)
  File "/usr/local/lib/python3.10/dist-packages/starlette/routing.py", line 66, in app
    response = await func(request)
  File "/usr/local/lib/python3.10/dist-packages/fastapi/routing.py", line 237, in app
    raw_response = await run_endpoint_function(
  File "/usr/local/lib/python3.10/dist-packages/fastapi/routing.py", line 163, in run_endpoint_function
    return await dependant.call(**values)
  File "/./service_main.py", line 105, in read_presentation
    author = get_author(presentation.author_id)
  File "/./circuitbreaker.py", line 159, in wrapper
    return call(function, *args, **kwargs)
  File "/./circuitbreaker.py", line 170, in call
    return func(*args, **kwargs)
  File "/./service_main.py", line 76, in get_author
    logging.warning(">>> Error Connecting:", errc)
Message: '>>> Error Connecting:'
Arguments: (ConnectionError(MaxRetryError("HTTPConnectionPool(host='service_author', port=8081): Max retries exceeded with url: /authors/2 (Caused by NewConnectionError('<urllib3.connection.HTTPConnection object at 0x7f8afb55f2e0>: Failed to establish a new connection: [Errno -2] Name or service not known'))")),)
WARNING:root:Circuit "get_author" is "closed", failures: 2
WARNING:root:
--- Logging error ---
Traceback (most recent call last):
  File "/usr/local/lib/python3.10/dist-packages/urllib3/connection.py", line 174, in _new_conn
    conn = connection.create_connection(
  File "/usr/local/lib/python3.10/dist-packages/urllib3/util/connection.py", line 72, in create_connection
    for res in socket.getaddrinfo(host, port, family, socket.SOCK_STREAM):
  File "/usr/lib/python3.10/socket.py", line 955, in getaddrinfo
    for res in _socket.getaddrinfo(host, port, family, type, proto, flags):
socket.gaierror: [Errno -2] Name or service not known

During handling of the above exception, another exception occurred:

Traceback (most recent call last):
  File "/usr/local/lib/python3.10/dist-packages/urllib3/connectionpool.py", line 703, in urlopen
    httplib_response = self._make_request(
  File "/usr/local/lib/python3.10/dist-packages/urllib3/connectionpool.py", line 398, in _make_request
    conn.request(method, url, **httplib_request_kw)
  File "/usr/local/lib/python3.10/dist-packages/urllib3/connection.py", line 239, in request
    super(HTTPConnection, self).request(method, url, body=body, headers=headers)
  File "/usr/lib/python3.10/http/client.py", line 1282, in request
    self._send_request(method, url, body, headers, encode_chunked)
  File "/usr/lib/python3.10/http/client.py", line 1328, in _send_request
    self.endheaders(body, encode_chunked=encode_chunked)
  File "/usr/lib/python3.10/http/client.py", line 1277, in endheaders
    self._send_output(message_body, encode_chunked=encode_chunked)
  File "/usr/lib/python3.10/http/client.py", line 1037, in _send_output
    self.send(msg)
  File "/usr/lib/python3.10/http/client.py", line 975, in send
    self.connect()
  File "/usr/local/lib/python3.10/dist-packages/urllib3/connection.py", line 205, in connect
    conn = self._new_conn()
  File "/usr/local/lib/python3.10/dist-packages/urllib3/connection.py", line 186, in _new_conn
    raise NewConnectionError(
urllib3.exceptions.NewConnectionError: <urllib3.connection.HTTPConnection object at 0x7f8afb3803d0>: Failed to establish a new connection: [Errno -2] Name or service not known

During handling of the above exception, another exception occurred:

Traceback (most recent call last):
  File "/usr/local/lib/python3.10/dist-packages/requests/adapters.py", line 489, in send
    resp = conn.urlopen(
  File "/usr/local/lib/python3.10/dist-packages/urllib3/connectionpool.py", line 787, in urlopen
    retries = retries.increment(
  File "/usr/local/lib/python3.10/dist-packages/urllib3/util/retry.py", line 592, in increment
    raise MaxRetryError(_pool, url, error or ResponseError(cause))
urllib3.exceptions.MaxRetryError: HTTPConnectionPool(host='service_author', port=8081): Max retries exceeded with url: /authors/2 (Caused by NewConnectionError('<urllib3.connection.HTTPConnection object at 0x7f8afb3803d0>: Failed to establish a new connection: [Errno -2] Name or service not known'))

During handling of the above exception, another exception occurred:

Traceback (most recent call last):
  File "/./service_main.py", line 74, in get_author
    response_author = requests.get("http://" + service_author + "/authors/" + str(id))
  File "/usr/local/lib/python3.10/dist-packages/requests/api.py", line 73, in get
    return request("get", url, params=params, **kwargs)
  File "/usr/local/lib/python3.10/dist-packages/requests/api.py", line 59, in request
    return session.request(method=method, url=url, **kwargs)
  File "/usr/local/lib/python3.10/dist-packages/requests/sessions.py", line 587, in request
    resp = self.send(prep, **send_kwargs)
  File "/usr/local/lib/python3.10/dist-packages/requests/sessions.py", line 701, in send
    r = adapter.send(request, **kwargs)
  File "/usr/local/lib/python3.10/dist-packages/requests/adapters.py", line 565, in send
    raise ConnectionError(e, request=request)
requests.exceptions.ConnectionError: HTTPConnectionPool(host='service_author', port=8081): Max retries exceeded with url: /authors/2 (Caused by NewConnectionError('<urllib3.connection.HTTPConnection object at 0x7f8afb3803d0>: Failed to establish a new connection: [Errno -2] Name or service not known'))

During handling of the above exception, another exception occurred:

Traceback (most recent call last):
  File "/usr/lib/python3.10/logging/__init__.py", line 1100, in emit
    msg = self.format(record)
  File "/usr/lib/python3.10/logging/__init__.py", line 943, in format
    return fmt.format(record)
  File "/usr/lib/python3.10/logging/__init__.py", line 678, in format
    record.message = record.getMessage()
  File "/usr/lib/python3.10/logging/__init__.py", line 368, in getMessage
    msg = msg % self.args
TypeError: not all arguments converted during string formatting
Call stack:
  File "<string>", line 1, in <module>
  File "/usr/lib/python3.10/multiprocessing/spawn.py", line 116, in spawn_main
    exitcode = _main(fd, parent_sentinel)
  File "/usr/lib/python3.10/multiprocessing/spawn.py", line 129, in _main
    return self._bootstrap(parent_sentinel)
  File "/usr/lib/python3.10/multiprocessing/process.py", line 314, in _bootstrap
    self.run()
  File "/usr/lib/python3.10/multiprocessing/process.py", line 108, in run
    self._target(*self._args, **self._kwargs)
  File "/usr/local/lib/python3.10/dist-packages/uvicorn/_subprocess.py", line 76, in subprocess_started
    target(sockets=sockets)
  File "/usr/local/lib/python3.10/dist-packages/uvicorn/server.py", line 60, in run
    return asyncio.run(self.serve(sockets=sockets))
  File "/usr/lib/python3.10/asyncio/runners.py", line 44, in run
    return loop.run_until_complete(main)
  File "/usr/lib/python3.10/asyncio/base_events.py", line 633, in run_until_complete
    self.run_forever()
  File "/usr/lib/python3.10/asyncio/base_events.py", line 600, in run_forever
    self._run_once()
  File "/usr/lib/python3.10/asyncio/base_events.py", line 1896, in _run_once
    handle._run()
  File "/usr/lib/python3.10/asyncio/events.py", line 80, in _run
    self._context.run(self._callback, *self._args)
  File "/usr/local/lib/python3.10/dist-packages/uvicorn/protocols/http/httptools_impl.py", line 419, in run_asgi
    result = await app(  # type: ignore[func-returns-value]
  File "/usr/local/lib/python3.10/dist-packages/uvicorn/middleware/proxy_headers.py", line 78, in __call__
    return await self.app(scope, receive, send)
  File "/usr/local/lib/python3.10/dist-packages/fastapi/applications.py", line 271, in __call__
    await super().__call__(scope, receive, send)
  File "/usr/local/lib/python3.10/dist-packages/starlette/applications.py", line 118, in __call__
    await self.middleware_stack(scope, receive, send)
  File "/usr/local/lib/python3.10/dist-packages/starlette/middleware/errors.py", line 162, in __call__
    await self.app(scope, receive, _send)
  File "/usr/local/lib/python3.10/dist-packages/starlette/middleware/exceptions.py", line 68, in __call__
    await self.app(scope, receive, sender)
  File "/usr/local/lib/python3.10/dist-packages/fastapi/middleware/asyncexitstack.py", line 18, in __call__
    await self.app(scope, receive, send)
  File "/usr/local/lib/python3.10/dist-packages/starlette/routing.py", line 706, in __call__
    await route.handle(scope, receive, send)
  File "/usr/local/lib/python3.10/dist-packages/starlette/routing.py", line 276, in handle
    await self.app(scope, receive, send)
  File "/usr/local/lib/python3.10/dist-packages/starlette/routing.py", line 66, in app
    response = await func(request)
  File "/usr/local/lib/python3.10/dist-packages/fastapi/routing.py", line 237, in app
    raw_response = await run_endpoint_function(
  File "/usr/local/lib/python3.10/dist-packages/fastapi/routing.py", line 163, in run_endpoint_function
    return await dependant.call(**values)
  File "/./service_main.py", line 105, in read_presentation
    author = get_author(presentation.author_id)
  File "/./circuitbreaker.py", line 159, in wrapper
    return call(function, *args, **kwargs)
  File "/./circuitbreaker.py", line 170, in call
    return func(*args, **kwargs)
  File "/./service_main.py", line 76, in get_author
    logging.warning(">>> Error Connecting:", errc)
Message: '>>> Error Connecting:'
Arguments: (ConnectionError(MaxRetryError("HTTPConnectionPool(host='service_author', port=8081): Max retries exceeded with url: /authors/2 (Caused by NewConnectionError('<urllib3.connection.HTTPConnection object at 0x7f8afb3803d0>: Failed to establish a new connection: [Errno -2] Name or service not known'))")),)
WARNING:root:Circuit "get_author" is "closed", failures: 3
WARNING:root:
--- Logging error ---
Traceback (most recent call last):
  File "/usr/local/lib/python3.10/dist-packages/urllib3/connection.py", line 174, in _new_conn
    conn = connection.create_connection(
  File "/usr/local/lib/python3.10/dist-packages/urllib3/util/connection.py", line 72, in create_connection
    for res in socket.getaddrinfo(host, port, family, socket.SOCK_STREAM):
  File "/usr/lib/python3.10/socket.py", line 955, in getaddrinfo
    for res in _socket.getaddrinfo(host, port, family, type, proto, flags):
socket.gaierror: [Errno -2] Name or service not known

During handling of the above exception, another exception occurred:

Traceback (most recent call last):
  File "/usr/local/lib/python3.10/dist-packages/urllib3/connectionpool.py", line 703, in urlopen
    httplib_response = self._make_request(
  File "/usr/local/lib/python3.10/dist-packages/urllib3/connectionpool.py", line 398, in _make_request
    conn.request(method, url, **httplib_request_kw)
  File "/usr/local/lib/python3.10/dist-packages/urllib3/connection.py", line 239, in request
    super(HTTPConnection, self).request(method, url, body=body, headers=headers)
  File "/usr/lib/python3.10/http/client.py", line 1282, in request
    self._send_request(method, url, body, headers, encode_chunked)
  File "/usr/lib/python3.10/http/client.py", line 1328, in _send_request
    self.endheaders(body, encode_chunked=encode_chunked)
  File "/usr/lib/python3.10/http/client.py", line 1277, in endheaders
    self._send_output(message_body, encode_chunked=encode_chunked)
  File "/usr/lib/python3.10/http/client.py", line 1037, in _send_output
    self.send(msg)
  File "/usr/lib/python3.10/http/client.py", line 975, in send
    self.connect()
  File "/usr/local/lib/python3.10/dist-packages/urllib3/connection.py", line 205, in connect
    conn = self._new_conn()
  File "/usr/local/lib/python3.10/dist-packages/urllib3/connection.py", line 186, in _new_conn
    raise NewConnectionError(
urllib3.exceptions.NewConnectionError: <urllib3.connection.HTTPConnection object at 0x7f8afb536620>: Failed to establish a new connection: [Errno -2] Name or service not known

During handling of the above exception, another exception occurred:

Traceback (most recent call last):
  File "/usr/local/lib/python3.10/dist-packages/requests/adapters.py", line 489, in send
    resp = conn.urlopen(
  File "/usr/local/lib/python3.10/dist-packages/urllib3/connectionpool.py", line 787, in urlopen
    retries = retries.increment(
  File "/usr/local/lib/python3.10/dist-packages/urllib3/util/retry.py", line 592, in increment
    raise MaxRetryError(_pool, url, error or ResponseError(cause))
urllib3.exceptions.MaxRetryError: HTTPConnectionPool(host='service_author', port=8081): Max retries exceeded with url: /authors/2 (Caused by NewConnectionError('<urllib3.connection.HTTPConnection object at 0x7f8afb536620>: Failed to establish a new connection: [Errno -2] Name or service not known'))

During handling of the above exception, another exception occurred:

Traceback (most recent call last):
  File "/./service_main.py", line 74, in get_author
    response_author = requests.get("http://" + service_author + "/authors/" + str(id))
  File "/usr/local/lib/python3.10/dist-packages/requests/api.py", line 73, in get
    return request("get", url, params=params, **kwargs)
  File "/usr/local/lib/python3.10/dist-packages/requests/api.py", line 59, in request
    return session.request(method=method, url=url, **kwargs)
  File "/usr/local/lib/python3.10/dist-packages/requests/sessions.py", line 587, in request
    resp = self.send(prep, **send_kwargs)
  File "/usr/local/lib/python3.10/dist-packages/requests/sessions.py", line 701, in send
    r = adapter.send(request, **kwargs)
  File "/usr/local/lib/python3.10/dist-packages/requests/adapters.py", line 565, in send
    raise ConnectionError(e, request=request)
requests.exceptions.ConnectionError: HTTPConnectionPool(host='service_author', port=8081): Max retries exceeded with url: /authors/2 (Caused by NewConnectionError('<urllib3.connection.HTTPConnection object at 0x7f8afb536620>: Failed to establish a new connection: [Errno -2] Name or service not known'))

During handling of the above exception, another exception occurred:

Traceback (most recent call last):
  File "/usr/lib/python3.10/logging/__init__.py", line 1100, in emit
    msg = self.format(record)
  File "/usr/lib/python3.10/logging/__init__.py", line 943, in format
    return fmt.format(record)
  File "/usr/lib/python3.10/logging/__init__.py", line 678, in format
    record.message = record.getMessage()
  File "/usr/lib/python3.10/logging/__init__.py", line 368, in getMessage
    msg = msg % self.args
TypeError: not all arguments converted during string formatting
Call stack:
  File "<string>", line 1, in <module>
  File "/usr/lib/python3.10/multiprocessing/spawn.py", line 116, in spawn_main
    exitcode = _main(fd, parent_sentinel)
  File "/usr/lib/python3.10/multiprocessing/spawn.py", line 129, in _main
    return self._bootstrap(parent_sentinel)
  File "/usr/lib/python3.10/multiprocessing/process.py", line 314, in _bootstrap
    self.run()
  File "/usr/lib/python3.10/multiprocessing/process.py", line 108, in run
    self._target(*self._args, **self._kwargs)
  File "/usr/local/lib/python3.10/dist-packages/uvicorn/_subprocess.py", line 76, in subprocess_started
    target(sockets=sockets)
  File "/usr/local/lib/python3.10/dist-packages/uvicorn/server.py", line 60, in run
    return asyncio.run(self.serve(sockets=sockets))
  File "/usr/lib/python3.10/asyncio/runners.py", line 44, in run
    return loop.run_until_complete(main)
  File "/usr/lib/python3.10/asyncio/base_events.py", line 633, in run_until_complete
    self.run_forever()
  File "/usr/lib/python3.10/asyncio/base_events.py", line 600, in run_forever
    self._run_once()
  File "/usr/lib/python3.10/asyncio/base_events.py", line 1896, in _run_once
    handle._run()
  File "/usr/lib/python3.10/asyncio/events.py", line 80, in _run
    self._context.run(self._callback, *self._args)
INFO:     172.19.0.1:56308 - "GET /presentationsAndAuthor/Second%20Presentation HTTP/1.1" 500 Internal Server Error
  File "/usr/local/lib/python3.10/dist-packages/uvicorn/protocols/http/httptools_impl.py", line 419, in run_asgi
    result = await app(  # type: ignore[func-returns-value]
  File "/usr/local/lib/python3.10/dist-packages/uvicorn/middleware/proxy_headers.py", line 78, in __call__
    return await self.app(scope, receive, send)
  File "/usr/local/lib/python3.10/dist-packages/fastapi/applications.py", line 271, in __call__
    await super().__call__(scope, receive, send)
  File "/usr/local/lib/python3.10/dist-packages/starlette/applications.py", line 118, in __call__
    await self.middleware_stack(scope, receive, send)
  File "/usr/local/lib/python3.10/dist-packages/starlette/middleware/errors.py", line 162, in __call__
    await self.app(scope, receive, _send)
  File "/usr/local/lib/python3.10/dist-packages/starlette/middleware/exceptions.py", line 68, in __call__
    await self.app(scope, receive, sender)
  File "/usr/local/lib/python3.10/dist-packages/fastapi/middleware/asyncexitstack.py", line 18, in __call__
    await self.app(scope, receive, send)
  File "/usr/local/lib/python3.10/dist-packages/starlette/routing.py", line 706, in __call__
    await route.handle(scope, receive, send)
  File "/usr/local/lib/python3.10/dist-packages/starlette/routing.py", line 276, in handle
    await self.app(scope, receive, send)
  File "/usr/local/lib/python3.10/dist-packages/starlette/routing.py", line 66, in app
    response = await func(request)
  File "/usr/local/lib/python3.10/dist-packages/fastapi/routing.py", line 237, in app
    raw_response = await run_endpoint_function(
  File "/usr/local/lib/python3.10/dist-packages/fastapi/routing.py", line 163, in run_endpoint_function
    return await dependant.call(**values)
  File "/./service_main.py", line 105, in read_presentation
    author = get_author(presentation.author_id)
  File "/./circuitbreaker.py", line 159, in wrapper
    return call(function, *args, **kwargs)
  File "/./circuitbreaker.py", line 170, in call
    return func(*args, **kwargs)
  File "/./service_main.py", line 76, in get_author
    logging.warning(">>> Error Connecting:", errc)
Message: '>>> Error Connecting:'
Arguments: (ConnectionError(MaxRetryError("HTTPConnectionPool(host='service_author', port=8081): Max retries exceeded with url: /authors/2 (Caused by NewConnectionError('<urllib3.connection.HTTPConnection object at 0x7f8afb536620>: Failed to establish a new connection: [Errno -2] Name or service not known'))")),)
WARNING:root:Circuit "get_author" is "closed", failures: 4
WARNING:root:
--- Logging error ---
Traceback (most recent call last):
  File "/usr/local/lib/python3.10/dist-packages/urllib3/connection.py", line 174, in _new_conn
    conn = connection.create_connection(
  File "/usr/local/lib/python3.10/dist-packages/urllib3/util/connection.py", line 72, in create_connection
    for res in socket.getaddrinfo(host, port, family, socket.SOCK_STREAM):
  File "/usr/lib/python3.10/socket.py", line 955, in getaddrinfo
    for res in _socket.getaddrinfo(host, port, family, type, proto, flags):
socket.gaierror: [Errno -2] Name or service not known

During handling of the above exception, another exception occurred:

Traceback (most recent call last):
  File "/usr/local/lib/python3.10/dist-packages/urllib3/connectionpool.py", line 703, in urlopen
    httplib_response = self._make_request(
  File "/usr/local/lib/python3.10/dist-packages/urllib3/connectionpool.py", line 398, in _make_request
    conn.request(method, url, **httplib_request_kw)
  File "/usr/local/lib/python3.10/dist-packages/urllib3/connection.py", line 239, in request
    super(HTTPConnection, self).request(method, url, body=body, headers=headers)
  File "/usr/lib/python3.10/http/client.py", line 1282, in request
    self._send_request(method, url, body, headers, encode_chunked)
INFO:     172.19.0.1:56308 - "GET /presentationsAndAuthor/Second%20Presentation HTTP/1.1" 500 Internal Server Error
  File "/usr/lib/python3.10/http/client.py", line 1328, in _send_request
    self.endheaders(body, encode_chunked=encode_chunked)
  File "/usr/lib/python3.10/http/client.py", line 1277, in endheaders
    self._send_output(message_body, encode_chunked=encode_chunked)
  File "/usr/lib/python3.10/http/client.py", line 1037, in _send_output
    self.send(msg)
  File "/usr/lib/python3.10/http/client.py", line 975, in send
    self.connect()
  File "/usr/local/lib/python3.10/dist-packages/urllib3/connection.py", line 205, in connect
    conn = self._new_conn()
  File "/usr/local/lib/python3.10/dist-packages/urllib3/connection.py", line 186, in _new_conn
    raise NewConnectionError(
urllib3.exceptions.NewConnectionError: <urllib3.connection.HTTPConnection object at 0x7f8afb381300>: Failed to establish a new connection: [Errno -2] Name or service not known

During handling of the above exception, another exception occurred:

Traceback (most recent call last):
  File "/usr/local/lib/python3.10/dist-packages/requests/adapters.py", line 489, in send
    resp = conn.urlopen(
  File "/usr/local/lib/python3.10/dist-packages/urllib3/connectionpool.py", line 787, in urlopen
    retries = retries.increment(
  File "/usr/local/lib/python3.10/dist-packages/urllib3/util/retry.py", line 592, in increment
    raise MaxRetryError(_pool, url, error or ResponseError(cause))
urllib3.exceptions.MaxRetryError: HTTPConnectionPool(host='service_author', port=8081): Max retries exceeded with url: /authors/2 (Caused by NewConnectionError('<urllib3.connection.HTTPConnection object at 0x7f8afb381300>: Failed to establish a new connection: [Errno -2] Name or service not known'))

During handling of the above exception, another exception occurred:

Traceback (most recent call last):
  File "/./service_main.py", line 74, in get_author
    response_author = requests.get("http://" + service_author + "/authors/" + str(id))
  File "/usr/local/lib/python3.10/dist-packages/requests/api.py", line 73, in get
    return request("get", url, params=params, **kwargs)
  File "/usr/local/lib/python3.10/dist-packages/requests/api.py", line 59, in request
    return session.request(method=method, url=url, **kwargs)
  File "/usr/local/lib/python3.10/dist-packages/requests/sessions.py", line 587, in request
    resp = self.send(prep, **send_kwargs)
  File "/usr/local/lib/python3.10/dist-packages/requests/sessions.py", line 701, in send
    r = adapter.send(request, **kwargs)
  File "/usr/local/lib/python3.10/dist-packages/requests/adapters.py", line 565, in send
    raise ConnectionError(e, request=request)
requests.exceptions.ConnectionError: HTTPConnectionPool(host='service_author', port=8081): Max retries exceeded with url: /authors/2 (Caused by NewConnectionError('<urllib3.connection.HTTPConnection object at 0x7f8afb381300>: Failed to establish a new connection: [Errno -2] Name or service not known'))

During handling of the above exception, another exception occurred:

Traceback (most recent call last):
  File "/usr/lib/python3.10/logging/__init__.py", line 1100, in emit
    msg = self.format(record)
  File "/usr/lib/python3.10/logging/__init__.py", line 943, in format
    return fmt.format(record)
  File "/usr/lib/python3.10/logging/__init__.py", line 678, in format
    record.message = record.getMessage()
  File "/usr/lib/python3.10/logging/__init__.py", line 368, in getMessage
    msg = msg % self.args
TypeError: not all arguments converted during string formatting
Call stack:
  File "<string>", line 1, in <module>
  File "/usr/lib/python3.10/multiprocessing/spawn.py", line 116, in spawn_main
    exitcode = _main(fd, parent_sentinel)
  File "/usr/lib/python3.10/multiprocessing/spawn.py", line 129, in _main
    return self._bootstrap(parent_sentinel)
  File "/usr/lib/python3.10/multiprocessing/process.py", line 314, in _bootstrap
    self.run()
  File "/usr/lib/python3.10/multiprocessing/process.py", line 108, in run
    self._target(*self._args, **self._kwargs)
  File "/usr/local/lib/python3.10/dist-packages/uvicorn/_subprocess.py", line 76, in subprocess_started
    target(sockets=sockets)
  File "/usr/local/lib/python3.10/dist-packages/uvicorn/server.py", line 60, in run
    return asyncio.run(self.serve(sockets=sockets))
  File "/usr/lib/python3.10/asyncio/runners.py", line 44, in run
    return loop.run_until_complete(main)
  File "/usr/lib/python3.10/asyncio/base_events.py", line 633, in run_until_complete
    self.run_forever()
  File "/usr/lib/python3.10/asyncio/base_events.py", line 600, in run_forever
    self._run_once()
  File "/usr/lib/python3.10/asyncio/base_events.py", line 1896, in _run_once
    handle._run()
  File "/usr/lib/python3.10/asyncio/events.py", line 80, in _run
    self._context.run(self._callback, *self._args)
  File "/usr/local/lib/python3.10/dist-packages/uvicorn/protocols/http/httptools_impl.py", line 419, in run_asgi
    result = await app(  # type: ignore[func-returns-value]
  File "/usr/local/lib/python3.10/dist-packages/uvicorn/middleware/proxy_headers.py", line 78, in __call__
    return await self.app(scope, receive, send)
  File "/usr/local/lib/python3.10/dist-packages/fastapi/applications.py", line 271, in __call__
    await super().__call__(scope, receive, send)
  File "/usr/local/lib/python3.10/dist-packages/starlette/applications.py", line 118, in __call__
    await self.middleware_stack(scope, receive, send)
  File "/usr/local/lib/python3.10/dist-packages/starlette/middleware/errors.py", line 162, in __call__
    await self.app(scope, receive, _send)
  File "/usr/local/lib/python3.10/dist-packages/starlette/middleware/exceptions.py", line 68, in __call__
    await self.app(scope, receive, sender)
  File "/usr/local/lib/python3.10/dist-packages/fastapi/middleware/asyncexitstack.py", line 18, in __call__
    await self.app(scope, receive, send)
  File "/usr/local/lib/python3.10/dist-packages/starlette/routing.py", line 706, in __call__
    await route.handle(scope, receive, send)
  File "/usr/local/lib/python3.10/dist-packages/starlette/routing.py", line 276, in handle
    await self.app(scope, receive, send)
  File "/usr/local/lib/python3.10/dist-packages/starlette/routing.py", line 66, in app
    response = await func(request)
  File "/usr/local/lib/python3.10/dist-packages/fastapi/routing.py", line 237, in app
    raw_response = await run_endpoint_function(
  File "/usr/local/lib/python3.10/dist-packages/fastapi/routing.py", line 163, in run_endpoint_function
    return await dependant.call(**values)
  File "/./service_main.py", line 105, in read_presentation
    author = get_author(presentation.author_id)
  File "/./circuitbreaker.py", line 159, in wrapper
    return call(function, *args, **kwargs)
  File "/./circuitbreaker.py", line 170, in call
    return func(*args, **kwargs)
  File "/./service_main.py", line 76, in get_author
    logging.warning(">>> Error Connecting:", errc)
Message: '>>> Error Connecting:'
Arguments: (ConnectionError(MaxRetryError("HTTPConnectionPool(host='service_author', port=8081): Max retries exceeded with url: /authors/2 (Caused by NewConnectionError('<urllib3.connection.HTTPConnection object at 0x7f8afb381300>: Failed to establish a new connection: [Errno -2] Name or service not known'))")),)
WARNING:root:Circuit "get_author" is "open", failures: 5
WARNING:root:
CRITICAL:root:Circuit OPEN
WARNING:root:Circuit "get_author" is "open", failures: 5
WARNING:root:
WARNING:root:Circuit "get_author" is "open", failures: 5
WARNING:root:
CRITICAL:root:Circuit OPEN
WARNING:root:Circuit "get_author" is "open", failures: 5
WARNING:root:
WARNING:root:Circuit "get_author" is "open", failures: 5
WARNING:root:
WARNING:root:Circuit "get_author" is "open", failures: 5
WARNING:root:
WARNING:root:Circuit "get_author" is "open", failures: 5
WARNING:root:
WARNING:root:Circuit "get_author" is "open", failures: 5
WARNING:root:
WARNING:root:Circuit "get_author" is "open", failures: 5
WARNING:root:
WARNING:root:Circuit "get_author" is "open", failures: 5
WARNING:root:
WARNING:root:Circuit "get_author" is "half_open", failures: 5
WARNING:root:
WARNING:root:Circuit "get_author" is "half_open", failures: 5
INFO:     172.19.0.1:56308 - "GET /presentationsAndAuthor/Second%20Presentation HTTP/1.1" 500 Internal Server Error
INFO:     172.19.0.1:56308 - "GET /presentationsAndAuthor/Second%20Presentation HTTP/1.1" 200 OK
INFO:     172.19.0.1:56308 - "GET /presentationsAndAuthor/Second%20Presentation HTTP/1.1" 200 OK
WARNING:root:
WARNING:root:Circuit "get_author" is "half_open", failures: 5
WARNING:root:
--- Logging error ---
Traceback (most recent call last):
  File "/usr/local/lib/python3.10/dist-packages/urllib3/connection.py", line 174, in _new_conn
    conn = connection.create_connection(
  File "/usr/local/lib/python3.10/dist-packages/urllib3/util/connection.py", line 72, in create_connection
    for res in socket.getaddrinfo(host, port, family, socket.SOCK_STREAM):
  File "/usr/lib/python3.10/socket.py", line 955, in getaddrinfo
    for res in _socket.getaddrinfo(host, port, family, type, proto, flags):
socket.gaierror: [Errno -2] Name or service not known

During handling of the above exception, another exception occurred:

Traceback (most recent call last):
  File "/usr/local/lib/python3.10/dist-packages/urllib3/connectionpool.py", line 703, in urlopen
    httplib_response = self._make_request(
  File "/usr/local/lib/python3.10/dist-packages/urllib3/connectionpool.py", line 398, in _make_request
    conn.request(method, url, **httplib_request_kw)
  File "/usr/local/lib/python3.10/dist-packages/urllib3/connection.py", line 239, in request
    super(HTTPConnection, self).request(method, url, body=body, headers=headers)
  File "/usr/lib/python3.10/http/client.py", line 1282, in request
    self._send_request(method, url, body, headers, encode_chunked)
  File "/usr/lib/python3.10/http/client.py", line 1328, in _send_request
    self.endheaders(body, encode_chunked=encode_chunked)
  File "/usr/lib/python3.10/http/client.py", line 1277, in endheaders
    self._send_output(message_body, encode_chunked=encode_chunked)
  File "/usr/lib/python3.10/http/client.py", line 1037, in _send_output
    self.send(msg)
  File "/usr/lib/python3.10/http/client.py", line 975, in send
    self.connect()
  File "/usr/local/lib/python3.10/dist-packages/urllib3/connection.py", line 205, in connect
    conn = self._new_conn()
  File "/usr/local/lib/python3.10/dist-packages/urllib3/connection.py", line 186, in _new_conn
    raise NewConnectionError(
urllib3.exceptions.NewConnectionError: <urllib3.connection.HTTPConnection object at 0x7f8afb382410>: Failed to establish a new connection: [Errno -2] Name or service not known

During handling of the above exception, another exception occurred:

Traceback (most recent call last):
  File "/usr/local/lib/python3.10/dist-packages/requests/adapters.py", line 489, in send
    resp = conn.urlopen(
  File "/usr/local/lib/python3.10/dist-packages/urllib3/connectionpool.py", line 787, in urlopen
    retries = retries.increment(
  File "/usr/local/lib/python3.10/dist-packages/urllib3/util/retry.py", line 592, in increment
    raise MaxRetryError(_pool, url, error or ResponseError(cause))
urllib3.exceptions.MaxRetryError: HTTPConnectionPool(host='service_author', port=8081): Max retries exceeded with url: /authors/2 (Caused by NewConnectionError('<urllib3.connection.HTTPConnection object at 0x7f8afb382410>: Failed to establish a new connection: [Errno -2] Name or service not known'))

During handling of the above exception, another exception occurred:

Traceback (most recent call last):
  File "/./service_main.py", line 74, in get_author
    response_author = requests.get("http://" + service_author + "/authors/" + str(id))
  File "/usr/local/lib/python3.10/dist-packages/requests/api.py", line 73, in get
    return request("get", url, params=params, **kwargs)
  File "/usr/local/lib/python3.10/dist-packages/requests/api.py", line 59, in request
    return session.request(method=method, url=url, **kwargs)
  File "/usr/local/lib/python3.10/dist-packages/requests/sessions.py", line 587, in request
    resp = self.send(prep, **send_kwargs)
  File "/usr/local/lib/python3.10/dist-packages/requests/sessions.py", line 701, in send
    r = adapter.send(request, **kwargs)
  File "/usr/local/lib/python3.10/dist-packages/requests/adapters.py", line 565, in send
    raise ConnectionError(e, request=request)
requests.exceptions.ConnectionError: HTTPConnectionPool(host='service_author', port=8081): Max retries exceeded with url: /authors/2 (Caused by NewConnectionError('<urllib3.connection.HTTPConnection object at 0x7f8afb382410>: Failed to establish a new connection: [Errno -2] Name or service not known'))

During handling of the above exception, another exception occurred:

Traceback (most recent call last):
  File "/usr/lib/python3.10/logging/__init__.py", line 1100, in emit
    msg = self.format(record)
  File "/usr/lib/python3.10/logging/__init__.py", line 943, in format
    return fmt.format(record)
  File "/usr/lib/python3.10/logging/__init__.py", line 678, in format
    record.message = record.getMessage()
  File "/usr/lib/python3.10/logging/__init__.py", line 368, in getMessage
    msg = msg % self.args
TypeError: not all arguments converted during string formatting
Call stack:
  File "<string>", line 1, in <module>
  File "/usr/lib/python3.10/multiprocessing/spawn.py", line 116, in spawn_main
    exitcode = _main(fd, parent_sentinel)
  File "/usr/lib/python3.10/multiprocessing/spawn.py", line 129, in _main
    return self._bootstrap(parent_sentinel)
  File "/usr/lib/python3.10/multiprocessing/process.py", line 314, in _bootstrap
    self.run()
  File "/usr/lib/python3.10/multiprocessing/process.py", line 108, in run
    self._target(*self._args, **self._kwargs)
  File "/usr/local/lib/python3.10/dist-packages/uvicorn/_subprocess.py", line 76, in subprocess_started
    target(sockets=sockets)
  File "/usr/local/lib/python3.10/dist-packages/uvicorn/server.py", line 60, in run
    return asyncio.run(self.serve(sockets=sockets))
  File "/usr/lib/python3.10/asyncio/runners.py", line 44, in run
    return loop.run_until_complete(main)
  File "/usr/lib/python3.10/asyncio/base_events.py", line 633, in run_until_complete
    self.run_forever()
  File "/usr/lib/python3.10/asyncio/base_events.py", line 600, in run_forever
    self._run_once()
  File "/usr/lib/python3.10/asyncio/base_events.py", line 1896, in _run_once
    handle._run()
  File "/usr/lib/python3.10/asyncio/events.py", line 80, in _run
    self._context.run(self._callback, *self._args)
  File "/usr/local/lib/python3.10/dist-packages/uvicorn/protocols/http/httptools_impl.py", line 419, in run_asgi
    result = await app(  # type: ignore[func-returns-value]
  File "/usr/local/lib/python3.10/dist-packages/uvicorn/middleware/proxy_headers.py", line 78, in __call__
    return await self.app(scope, receive, send)
  File "/usr/local/lib/python3.10/dist-packages/fastapi/applications.py", line 271, in __call__
    await super().__call__(scope, receive, send)
  File "/usr/local/lib/python3.10/dist-packages/starlette/applications.py", line 118, in __call__
    await self.middleware_stack(scope, receive, send)
  File "/usr/local/lib/python3.10/dist-packages/starlette/middleware/errors.py", line 162, in __call__
    await self.app(scope, receive, _send)
  File "/usr/local/lib/python3.10/dist-packages/starlette/middleware/exceptions.py", line 68, in __call__
    await self.app(scope, receive, sender)
  File "/usr/local/lib/python3.10/dist-packages/fastapi/middleware/asyncexitstack.py", line 18, in __call__
    await self.app(scope, receive, send)
  File "/usr/local/lib/python3.10/dist-packages/starlette/routing.py", line 706, in __call__
    await route.handle(scope, receive, send)
  File "/usr/local/lib/python3.10/dist-packages/starlette/routing.py", line 276, in handle
    await self.app(scope, receive, send)
  File "/usr/local/lib/python3.10/dist-packages/starlette/routing.py", line 66, in app
    response = await func(request)
  File "/usr/local/lib/python3.10/dist-packages/fastapi/routing.py", line 237, in app
    raw_response = await run_endpoint_function(
  File "/usr/local/lib/python3.10/dist-packages/fastapi/routing.py", line 163, in run_endpoint_function
    return await dependant.call(**values)
  File "/./service_main.py", line 105, in read_presentation
    author = get_author(presentation.author_id)
  File "/./circuitbreaker.py", line 159, in wrapper
    return call(function, *args, **kwargs)
  File "/./circuitbreaker.py", line 170, in call
    return func(*args, **kwargs)
  File "/./service_main.py", line 76, in get_author
    logging.warning(">>> Error Connecting:", errc)
Message: '>>> Error Connecting:'
Arguments: (ConnectionError(MaxRetryError("HTTPConnectionPool(host='service_author', port=8081): Max retries exceeded with url: /authors/2 (Caused by NewConnectionError('<urllib3.connection.HTTPConnection object at 0x7f8afb382410>: Failed to establish a new connection: [Errno -2] Name or service not known'))")),)
WARNING:root:Circuit "get_author" is "open", failures: 6
WARNING:root:
WARNING:root:Circuit "get_author" is "open", failures: 6
WARNING:root:
WARNING:root:Circuit "get_author" is "open", failures: 6
WARNING:root:
WARNING:root:Circuit "get_author" is "open", failures: 6
WARNING:root:
WARNING:root:Circuit "get_author" is "open", failures: 6
WARNING:root:
WARNING:root:Circuit "get_author" is "open", failures: 6
WARNING:root:
WARNING:root:Circuit "get_author" is "open", failures: 6
WARNING:root:
WARNING:root:Circuit "get_author" is "open", failures: 6
WARNING:root:
WARNING:root:Circuit "get_author" is "open", failures: 6
WARNING:root:
WARNING:root:Circuit "get_author" is "half_open", failures: 6
WARNING:root:
WARNING:root:Circuit "get_author" is "half_open", failures: 6
WARNING:root:
WARNING:root:Circuit "get_author" is "half_open", failures: 6
WARNING:root:
WARNING:root:Circuit "get_author" is "half_open", failures: 6
WARNING:root:
WARNING:root:Circuit "get_author" is "half_open", failures: 6
WARNING:root:
INFO:     172.19.0.1:56324 - "GET /presentationsAndAuthor/Second%20Presentation HTTP/1.1" 500 Internal Server Error
Griffiths
INFO:     172.19.0.1:56328 - "GET /presentationsAndAuthor/Second%20Presentation HTTP/1.1" 200 OK
WARNING:root:Circuit "get_author" is "closed", failures: 0
WARNING:root:
WARNING:root:Circuit "get_author" is "closed", failures: 0
WARNING:root:
WARNING:root:Circuit "get_author" is "closed", failures: 0
WARNING:root:
WARNING:root:Circuit "get_author" is "closed", failures: 0
WARNING:root:
WARNING:root:Circuit "get_author" is "closed", failures: 0
WARNING:root:
WARNING:root:Circuit "get_author" is "closed", failures: 0
WARNING:root:
WARNING:root:Circuit "get_author" is "closed", failures: 0
WARNING:root:
WARNING:root:Circuit "get_author" is "closed", failures: 0
WARNING:root:
WARNING:root:Circuit "get_author" is "closed", failures: 0
WARNING:root:
WARNING:root:Circuit "get_author" is "closed", failures: 0
WARNING:root:
WARNING:root:Circuit "get_author" is "closed", failures: 0
WARNING:root:
WARNING:root:Circuit "get_author" is "closed", failures: 0
WARNING:root:
WARNING:root:Circuit "get_author" is "closed", failures: 0
WARNING:root:
WARNING:root:Circuit "get_author" is "closed", failures: 0
WARNING:root:
WARNING:root:Circuit "get_author" is "closed", failures: 0
WARNING:root:
WARNING:root:Circuit "get_author" is "closed", failures: 0
WARNING:root: